Workbook

Sheet Population by MSA
B1: Atlanta-Sandy Springs-Roswell, GA Metro Area | C1: Boston-Cambridge-Newton, MA-NH Metro Area | D1: Chicago-Naperville-Elgin, IL-IN Metro Area | E1: Dallas-Fort Worth-Arlington, TX Metro Area | F1: Denver-Aurora-Centennial, CO Metro Area | G1: Detroit-Warren-Dearborn, MI Metro Area | H1: Houston-Pasadena-The Woodlands, TX Metro Area | I1: Los Angeles-Long Beach-Anaheim, CA Metro Area | J1: Miami-Fort Lauderdale-West Palm Beach, FL Metro Area | K1: Minneapolis-St. Paul-Bloomington, MN-WI Metro Area | L1: New York-Newark-Jersey City, NY-NJ Metro Area | M1: Orlando-Kissimmee-Sanford, FL Metro Area | N1: Philadelphia-Camden-Wilmington, PA-NJ-DE-MD Metro Area | O1: Phoenix-Mesa-Chandler, AZ Metro Area | P1: Riverside-San Bernardino-Ontario, CA Metro Area | Q1: San Diego-Chula Vista-Carlsbad, CA Metro Area | R1: San Francisco-Oakland-Fremont, CA Metro Area | S1: Seattle-Tacoma-Bellevue, WA Metro Area | T1: Tampa-St. Petersburg-Clearwater, FL Metro Area | U1: Washington-Arlington-Alexandria, DC-VA-MD-WV Metro Area | X1: USA
A2: observation_date | B2: POP | C2: POP | D2: POP | E2: POP | F2: POP | G2: POP | H2: POP | I2: POP | J2: POP | K2: POP | L2: POP | M2: POP | N2: POP | O2: POP | P2: POP | Q2: POP | R2: POP | S2: POP | T2: POP | U2: POP | W2: observation_date | X2: POPTOTUSA647NWDB
A3: DATE | B3: =B1&B2 -> Atlanta-Sandy Springs-Roswell, GA Metro AreaPOP | C3: =C1&C2 -> Boston-Cambridge-Newton, MA-NH Metro AreaPOP | D3: =D1&D2 -> Chicago-Naperville-Elgin, IL-IN Metro AreaPOP | E3: =E1&E2 -> Dallas-Fort Worth-Arlington, TX Metro AreaPOP | F3: =F1&F2 -> Denver-Aurora-Centennial, CO Metro AreaPOP | G3: =G1&G2 -> Detroit-Warren-Dearborn, MI Metro AreaPOP | H3: =H1&H2 -> Houston-Pasadena-The Woodlands, TX Metro AreaPOP | I3: =I1&I2 -> Los Angeles-Long Beach-Anaheim, CA Metro AreaPOP | ... U3: =U1&U2 -> Washington-Arlington-Alexandria, DC-VA-MD-WV Metro AreaPOP
A4: 36526 | B4: 4281.905 | C4: 4402.611 | D4: 9117.732 | E4: 5196.188 | F4: 2194.022 | G4: 4457.471 | H4: 4739.414 | I4: 12398.95 | J4: 5025.806 | K4: 2981.616 | L4: 18352.743 | M4: 1656.835 | N4: 5693.275 | O4: 3278.661 | P4: 3277.578 | Q4: 2824.987 | R4: 4136.658 | S4: 3052.379 | T4: 2404.273 | U4: 4821.031 | W4: 21916 | X4: 180671000
A5: 36892 | B5: 4432.95 | C5: 4443.31 | D5: 9192.501 | E5: 5354.623 | F5: 2246.785 | G5: 4479.232 | H5: 4851.189 | I5: 12525.736 | J5: 5120.256 | K5: 3024.111 | L5: 18490.029 | M5: 1708.955 | N5: 5722.541 | O5: 3388.445 | P5: 3376.256 | Q5: 2867.094 | R5: 4179.628 | S5: 3094.38 | T5: 2442.189 | U5: 4927.274 | W5: 22282 | X5: 183691000
A6: 37257 | B6: 4555.49 | C6: 4459.011 | D6: 9245.135 | E6: 5476.578 | F6: 2276.25 | G6: 4486.067 | H6: 4978.638 | I6: 12634.977 | J6: 5212.602 | K6: 3053.303 | L6: 18590.085 | M6: 1756.852 | N6: 5755.874 | O6: 3496.957 | P6: 3483.348 | Q6: 2901.235 | R6: 4165.678 | S6: 3121.895 | T6: 2483.575 | U6: 5014.571 | W6: 22647 | X6: 186538000
A7: 37622 | B7: 4673.146 | C7: 4458.187 | D7: 9286.162 | E7: 5582.033 | F7: 2297.441 | G7: 4492.756 | H7: 5084.017 | I7: 12717.433 | J7: 5280.671 | K7: 3078.253 | L7: 18671.32 | M7: 1803.474 | N7: 5787.788 | O7: 3600.163 | P7: 3611.625 | Q7: 2926.814 | R7: 4153.143 | S7: 3138.938 | T7: 2522.78 | U7: 5086.376 | W7: 23012 | X7: 189242000
A8: 37987 | B8: 4802.3 | C8: 4456.479 | D8: 9332.09 | E8: 5689.982 | F8: 2321.712 | G8: 4498.311 | H8: 5190.444 | I8: 12764.59 | J8: 5362.678 | K8: 3106.569 | L8: 18747.431 | M8: 1866.597 | N8: 5822.876 | O8: 3723.359 | P8: 3745.32 | Q8: 2935.672 | R8: 4143.522 | S8: 3163.703 | T8: 2578.104 | U8: 5158.524 | W8: 23377 | X8: 191889000
A9: 38353 | B9: 4947.012 | C9: 4458.891 | D9: 9362.08 | E9: 5816.407 | F9: 2353.518 | G9: 4494.398 | H9: 5299.567 | I9: 12761.175 | J9: 5443.159 | K9: 3132.772 | L9: 18798.114 | M9: 1939.766 | N9: 5850.621 | O9: 3884.588 | P9: 3861.335 | Q9: 2941.77 | R9: 4149.607 | S9: 3202.388 | T9: 2638.814 | U9: 5229.267 | W9: 23743 | X9: 194303000
A10: 38718 | B10: 5119.641 | C10: 4473.477 | D10: 9398.855 | E10: 5999.411 | F10: 2399.62 | G10: 4484.542 | H10: 5484.883 | I10: 12713.66 | J10: 5466.743 | K10: 3167.666 | L10: 18825.633 | M10: 1999.994 | N10: 5880.912 | O10: 4046.571 | P10: 3968.504 | Q10: 2947.222 | R10: 4162.783 | S10: 3259.945 | T10: 2684.639 | U10: 5265.012 | W10: 24108 | X10: 196560000
A11: 39083 | B11: 5267.527 | C11: 4503.921 | D11: 9451.936 | E11: 6156.652 | F11: 2449.476 | G11: 4456.582 | H11: 5597.674 | I11: 12693.603 | J11: 5465.183 | K11: 3204.196 | L11: 18901.167 | M11: 2034.878 | N11: 5912.678 | O11: 4175.595 | P11: 4048.913 | Q11: 2975.656 | R11: 4202.186 | S11: 3307.36 | T11: 2711.222 | U11: 5313.033 | W11: 24473 | X11: 198712000
A12: 39448 | B12: 5385.586 | C12: 4544.705 | D12: 9515.636 | E12: 6301.085 | F12: 2500.384 | G12: 4423.781 | H12: 5726.705 | I12: 12768.395 | J12: 5501.752 | K12: 3237.612 | L12: 18968.501 | M12: 2060.968 | N12: 5940.496 | O12: 4287.323 | P12: 4092.831 | Q12: 3019.274 | R12: 4260.236 | S12: 3356.637 | T12: 2730.007 | U12: 5377.936 | W12: 24838 | X12: 200706000
A13: 39814 | B13: 5475.213 | C13: 4588.68 | D13: 9580.567 | E13: 6447.615 | F13: 2552.195 | G13: 4403.437 | H13: 5867.489 | I13: 12874.797 | J13: 5547.051 | K13: 3269.814 | L13: 19069.796 | M13: 2082.421 | N13: 5968.252 | O13: 4364.094 | P13: 4143.113 | Q13: 3053.793 | R13: 4317.853 | S13: 3407.848 | T13: 2747.272 | U13: 5476.241 | W13: 25204 | X13: 202677000
A14: 40179 | B14: 5302.733 | C14: 4566.448 | D14: 9470.661 | E14: 6392.097 | F14: 2554.588 | G14: 4291.281 | H14: 5947.185 | I14: 12838.023 | J14: 5583.46 | K14: 3340.07 | L14: 18923.437 | M14: 2139.227 | N14: 5971.202 | O14: 4204.289 | P14: 4242.365 | Q14: 3103.26 | R14: 4343.886 | S14: 3449.355 | T14: 2788.433 | U14: 5678.733 | W14: 25569 | X14: 205052000
A15: 40544 | B15: 5367.069 | C15: 4610.267 | D15: 9500.919 | E15: 6510.55 | F15: 2603.261 | G15: 4291.613 | H15: 6056.008 | I15: 12923.899 | J15: 5668.482 | K15: 3373.773 | L15: 19053.124 | M15: 2176.297 | N15: 5996.995 | O15: 4253.485 | P15: 4294.436 | Q15: 3137.236 | R15: 4396.273 | S15: 3504.376 | T15: 2813.619 | U15: 5783.752 | W15: 25934 | X15: 207661000
... A26: 44562 | B26: 6222.106 | C26: 4931.775 | D26: 9441.957 | E26: 7973.603 | F26: 2985.871 | G26: 4358.51 | H26: 7340.118 | I26: 12906.936 | J26: 6211.194 | K26: 3696.911 | L26: 19617.869 | M26: 2783.767 | N26: 6252.024 | O26: 5029.933 | P26: 4675.657 | Q26: 3283.755 | R26: 4579.599 | S26: 4040.08 | T26: 3306.285 | U26: 6289.81 | W26: 29952 | X26: 231664000
A27: 44927 | C27: 4967.266 | E27: 8166.11 | G27: 4369.59 | I27: 12886.4 | J27: 6334.517 | K27: 3722.476 | M27: 2864.544 | N27: 6280.902 | O27: 5102.02 | P27: 4704.354 | Q27: 3285.89 | S27: 4078.828 | T27: 3374.078 | U27: 6345.881 | W27: 30317 | X27: 233792000
A28: 45292 | C28: 5025.517 | E28: 8344.032 | G28: 4400.578 | I28: 12927.614 | J28: 6457.988 | K28: 3757.952 | M28: 2940.513 | N28: 6330.422 | O28: 5186.958 | P28: 4744.214 | Q28: 3298.799 | S28: 4145.494 | T28: 3424.56 | U28: 6436.489 | W28: 30682 | X28: 235825000
W29: 31048 | X29: 237924000
W30: 31413 | X30: 240133000
W31: 31778 | X31: 242289000
W32: 32143 | X32: 244499000
W33: 32509 | X33: 246819000
W34: 32874 | X34: 249623000
W35: 33239 | X35: 252981000
W36: 33604 | X36: 256514000
W37: 33970 | X37: 259919000
W38: 34335 | X38: 263126000
W39: 34700 | X39: 266278000
W40: 35065 | X40: 269394000
... W68: 45292 | X68: 340110988
B1048576: New York-Newark-Jersey City, NY-NJ Metro Area | C1048576: Los Angeles-Long Beach-Anaheim, CA Metro Area | D1048576: Chicago-Naperville-Elgin, IL-IN Metro Area | E1048576: Dallas-Fort Worth-Arlington, TX Metro Area | F1048576: Houston-Pasadena-The Woodlands, TX Metro Area | G1048576: Miami-Fort Lauderdale-West Palm Beach, FL Metro Area | H1048576: Washington-Arlington-Alexandria, DC-VA-MD-WV Metro Area | I1048576: Atlanta-Sandy Springs-Roswell, GA Metro Area | J1048576: Philadelphia-Camden-Wilmington, PA-NJ-DE-MD Metro Area | K1048576: Phoenix-Mesa-Chandler, AZ Metro Area | L1048576: Boston-Cambridge-Newton, MA-NH Metro Area | M1048576: Riverside-San Bernardino-Ontario, CA Metro Area | N1048576: San Francisco-Oakland-Fremont, CA Metro Area | O1048576: Detroit-Warren-Dearborn, MI Metro Area | P1048576: Seattle-Tacoma-Bellevue, WA Metro Area | Q1048576: Minneapolis-St. Paul-Bloomington, MN-WI Metro Area | R1048576: Tampa-St. Petersburg-Clearwater, FL Metro Area | S1048576: San Diego-Chula Vista-Carlsbad, CA Metro Area | T1048576: Denver-Aurora-Centennial, CO Metro Area | U1048576: Orlando-Kissimmee-Sanford, FL Metro Area

Sheet GDP by MSA (GMP)
B1: Atlanta-Sandy Springs-Roswell, GA Metro Area | C1: Boston-Cambridge-Newton, MA-NH Metro Area | D1: Chicago-Naperville-Elgin, IL-IN Metro Area | E1: Dallas-Fort Worth-Arlington, TX Metro Area | F1: Denver-Aurora-Centennial, CO Metro Area | G1: Detroit-Warren-Dearborn, MI Metro Area | H1: Houston-Pasadena-The Woodlands, TX Metro Area | I1: Los Angeles-Long Beach-Anaheim, CA Metro Area | J1: Miami-Fort Lauderdale-West Palm Beach, FL Metro Area | K1: Minneapolis-St. Paul-Bloomington, MN-WI Metro Area | L1: New York-Newark-Jersey City, NY-NJ Metro Area | M1: Orlando-Kissimmee-Sanford, FL Metro Area | N1: Philadelphia-Camden-Wilmington, PA-NJ-DE-MD Metro Area | O1: Phoenix-Mesa-Chandler, AZ Metro Area | P1: Riverside-San Bernardino-Ontario, CA Metro Area | Q1: San Diego-Chula Vista-Carlsbad, CA Metro Area | R1: San Francisco-Oakland-Fremont, CA Metro Area | S1: Seattle-Tacoma-Bellevue, WA Metro Area | T1: Tampa-St. Petersburg-Clearwater, FL Metro Area | U1: Washington-Arlington-Alexandria, DC-VA-MD-WV Metro Area | W1: US Total
A2: observation_date | B2: GMP | C2: GMP | D2: GMP | E2: GMP | F2: GMP | G2: GMP | H2: GMP | I2: GMP | J2: GMP | K2: GMP | L2: GMP | M2: GMP | N2: GMP | O2: GMP | P2: GMP | Q2: GMP | R2: GMP | S2: GMP | T2: GMP | U2: GMP | W2: GDPC1 | X2: observation_date
A3: Date | B3: =B1&B2 -> Atlanta-Sandy Springs-Roswell, GA Metro AreaGMP | C3: =C1&C2 -> Boston-Cambridge-Newton, MA-NH Metro AreaGMP | D3: =D1&D2 -> Chicago-Naperville-Elgin, IL-IN Metro AreaGMP | E3: =E1&E2 -> Dallas-Fort Worth-Arlington, TX Metro AreaGMP | F3: =F1&F2 -> Denver-Aurora-Centennial, CO Metro AreaGMP | G3: =G1&G2 -> Detroit-Warren-Dearborn, MI Metro AreaGMP | H3: =H1&H2 -> Houston-Pasadena-The Woodlands, TX Metro AreaGMP | I3: =I1&I2 -> Los Angeles-Long Beach-Anaheim, CA Metro AreaGMP | ... U3: =U1&U2 -> Washington-Arlington-Alexandria, DC-VA-MD-WV Metro AreaGMP | W3: =W1&W2 -> US TotalGDPC1
A4: 36892 | B4: 271180.5 | C4: 304121.15 | D4: 551911.03 | E4: 288764.45 | F4: 141710.2 | G4: 235602.86 | H4: 300975.48 | I4: 676951.42 | J4: 246797.37 | K4: 188756.2 | L4: 1329496.2 | M4: 87051.253 | N4: 328508.53 | O4: 163040.2 | P4: 110343.73 | Q4: 152305.29 | R4: 322406.18 | S4: 205422.95 | T4: 107822.84 | U4: 355947.87 | W4: 2182.681 | X4: 17168
A5: 37257 | B5: 273930.85 | C5: 303344.19 | D5: 554209.1 | E5: 297113.28 | F5: 142187.03 | G5: 240796.48 | H5: 300134.19 | I5: 693293.04 | J5: 256640.85 | K5: 190963.4 | L5: 1318993.4 | M5: 90363.071 | N5: 331361.71 | O5: 168961.93 | P5: 116105.68 | Q5: 159296.69 | R5: 315859.6 | S5: 205596.77 | T5: 112664.67 | U5: 368535.88 | W5: 2176.892 | X5: 17258
A6: 37622 | B6: 282151.81 | C6: 310617.79 | D6: 563001.2 | E6: 302251.07 | F6: 142460.29 | G6: 247570.64 | H6: 301807.82 | I6: 722939.04 | J6: 266575.14 | K6: 200170.33 | L6: 1325356.5 | M6: 95216.336 | N6: 344556.12 | O6: 180979.05 | P6: 124213.73 | Q6: 167846.97 | R6: 320626.73 | S6: 208816.08 | T6: 118261.15 | U6: 382024.8 | W6: 2172.432 | X6: 17349
A7: 37987 | B7: 298232.22 | C7: 321080.66 | D7: 580916.4 | E7: 320064.34 | F7: 143624.91 | G7: 251004.55 | H7: 328635.01 | I7: 745816.64 | J7: 281757.82 | K7: 210296.67 | L7: 1354478 | M7: 102344.34 | N7: 358145.05 | O7: 191018.07 | P7: 132938.77 | Q7: 177125.12 | R7: 324229.32 | S7: 213810.26 | T7: 126024.52 | U7: 406258.62 | W7: 2206.452 | X7: 17441
A8: 38353 | B8: 313144.33 | C8: 329868.94 | D8: 595469.78 | E8: 336477.89 | F8: 149942.9 | G8: 255496.17 | H8: 334271.48 | I8: 770701.04 | J8: 297774.89 | K8: 216772.11 | L8: 1392492.4 | M8: 110181.74 | N8: 361393.18 | O8: 205774.08 | P8: 141765.46 | Q8: 186576.15 | R8: 338327.1 | S8: 229109.92 | T8: 132496.72 | U8: 425191.78 | W8: 2239.682 | X8: 17533
A9: 38718 | B9: 318677.89 | C9: 339387.18 | D9: 609831.44 | E9: 361594.85 | F9: 152563.48 | G9: 246974.97 | H9: 360553.52 | I9: 800980.47 | J9: 305552.22 | K9: 215931.46 | L9: 1434557.7 | M9: 113678.99 | N9: 365190.58 | O9: 216095.67 | P9: 147660 | Q9: 190800.98 | R9: 348300.97 | S9: 240142.73 | T9: 135683.53 | U9: 430691.45 | W9: 2276.69 | X9: 17624
A10: 39083 | B10: 322341.54 | C10: 351809.31 | D10: 620077.78 | E10: 376135.05 | F10: 159423.32 | G10: 245300.98 | H10: 390636.08 | I10: 811271.94 | J10: 307814.75 | K10: 218861.01 | L10: 1450433 | M10: 116664.51 | N10: 378819.77 | O10: 223034.4 | P10: 150418.93 | Q10: 194328.79 | R10: 351592.6 | S10: 257787.24 | T10: 137367.17 | U10: 438446.08 | W10: 2289.77 | X10: 17715
A11: 39448 | B11: 313422.43 | C11: 355943.71 | D11: 605115.08 | E11: 379888.57 | F11: 158853.78 | G11: 228556.22 | H11: 382270.92 | I11: 820920.39 | J11: 296843.79 | K11: 220552.8 | L11: 1425548.2 | M11: 113678.71 | N11: 389551.77 | O11: 218638.32 | P11: 147065.34 | Q11: 193238.64 | R11: 369652.89 | S11: 262875.6 | T11: 134074.36 | U11: 450704.44 | W11: 2292.364 | X11: 17807
A12: 39814 | B12: 298703.21 | C12: 353261.02 | D12: 584067.84 | E12: 368717.62 | F12: 153864.35 | G12: 203866.91 | H12: 379647.31 | I12: 781901.67 | J12: 277525.85 | K12: 211177.15 | L12: 1456569 | M12: 105856.69 | N12: 376898.1 | O12: 198621.9 | P12: 138295.41 | Q12: 183920.03 | R12: 354362.36 | S12: 253828.01 | T12: 129194.97 | U12: 450733.94 | W12: 2260.807 | X12: 17899
A13: 40179 | B13: 304596.01 | C13: 371428.59 | D13: 595377.26 | E13: 377056.75 | F13: 157506.81 | G13: 217989.88 | H13: 397507.09 | I13: 803814.35 | J13: 286921 | K13: 217937.93 | L13: 1505251.8 | M13: 107270.92 | N13: 385125.05 | O13: 200598.62 | P13: 140956.46 | Q13: 186568.77 | R13: 354658.03 | S13: 261975.13 | T13: 131029.53 | U13: 473111.81 | W13: 2253.128 | X13: 17989
A14: 40544 | B14: 311831.24 | C14: 379568.25 | D14: 606776.76 | E14: 391628.36 | F14: 160637.39 | G14: 227588.26 | H14: 408274.29 | I14: 816284.03 | J14: 287548.91 | K14: 223445.16 | L14: 1511139.5 | M14: 107456.42 | N14: 387482.26 | O14: 207388.7 | P14: 143846.93 | Q14: 190527.19 | R14: 358173.97 | S14: 271234.39 | T14: 130742.02 | U14: 482441.76 | W14: 2276.424 | X14: 18080
A15: 40909 | B15: 318110.62 | C15: 389780.97 | D15: 624494.55 | E15: 404523.39 | F15: 165465.43 | G15: 235803.33 | H15: 423174.91 | I15: 832108.35 | J15: 289047.95 | K15: 227583.21 | L15: 1574050.5 | M15: 110030.8 | N15: 397146.83 | O15: 215066.76 | P15: 144328.39 | Q15: 193126.87 | R15: 388091.69 | S15: 285805.22 | T15: 132984.38 | U15: 486294.47 | W15: 2257.352 | X15: 18172
... A26: 44927 | B26: 471655.71 | C26: 515386.13 | D26: 725745.07 | E26: 613381 | F26: 258989.25 | G26: 276493.74 | H26: 550795.54 | I26: 1075056.7 | J26: 431882.27 | K26: 286739.26 | L26: 1905237.4 | M26: 175313.25 | N26: 459530.62 | O26: 322794.26 | P26: 201185.09 | Q26: 261671.69 | R26: 681890.37 | S26: 487774.17 | T26: 198914.79 | U26: 600169.02 | W26: 2753.517 | X26: 19176
W27: 2843.941 | X27: 19268
W28: 2896.811 | X28: 19360
W29: 2919.206 | X29: 19450
W30: 2902.785 | X30: 19541
W31: 2858.845 | X31: 19633
W32: 2845.192 | X32: 19725
W33: 2848.305 | X33: 19815
W34: 2880.482 | X34: 19906
W35: 2936.852 | X35: 19998
W36: 3020.746 | X36: 20090
W37: 3069.91 | X37: 20180
W38: 3111.379 | X38: 20271
... W319: 24065.956 | X319: 45931

Sheet USA Employment NAICS 2 and Tota
A1: observation_date | B1: USA | C1: USA | D1: USA | E1: USA | F1: USA | G1: USA | H1: USA | I1: USA | J1: USA | K1: USA | L1: USA | M1: USA | N1: USA | O1: USA | P1: USA | Q1: USA | R1: USA | S1: USA | T1: USA | U1: USA | V1: USA
A2: DATE | B2: 21 - Mining, Quarrying, and Oil and Gas Extraction | C2: 48-49 - Transportation and Warehousing | D2: 22 - Utilities | E2: 52 - Finance and Insurance | F2: 53 - Real Estate and Rental and Leasing | G2: 54 - Professional, Scientific, and Technical Services | H2: 55 - Management of Companies and Enterprises | I2: 56 - Administrative and Support and Waste Management and Remediation Services | J2: 62 - Health Care and Social Assistance | K2: 71 - Arts, Entertainment, and Recreation | L2: 72 - Accommodation and Food Services | M2: 92 - Public Administration | N2: 31-33 - Manufacturing | O2: Total Employment | P2: 23 - Construction | Q2: 51 - Information | R2: 81 - Other Services (except Public Administration) | S2: 44-45 - Retail Trade | T2: 42 - Wholesale Trade | U2: observation_date | V2: 61 - Educational Services
A3: DATE | B3: =B1&B2 -> USA21 - Mining, Quarrying, and Oil and Gas Extraction | C3: =C1&C2 -> USA48-49 - Transportation and Warehousing | D3: =D1&D2 -> USA22 - Utilities | E3: =E1&E2 -> USA52 - Finance and Insurance | F3: =F1&F2 -> USA53 - Real Estate and Rental and Leasing | G3: =G1&G2 -> USA54 - Professional, Scientific, and Technical Services | H3: =H1&H2 -> USA55 - Management of Companies and Enterprises | I3: =I1&I2 -> USA56 - Administrative and Support and Waste Management and Remediation Services | ... T3: =T1&T2 -> USA42 - Wholesale Trade | U3: DATE | V3: =V1&V2 -> USA61 - Educational Services
A4: 14246 | M4: 3958 | N4: 9077 | O4: 29923 | P4: 1139 | Q4: 1112 | R4: 543 | S4: 3107.8 | T4: 1472.3 | U4: 31778 | V4: 1644
A5: 14277 | M5: 3947 | N5: 9175 | O5: 30100 | P5: 1162 | Q5: 1118 | R5: 544 | S5: 3121.8 | T5: 1473.3 | U5: 32143 | V5: 1771.8
A6: 14305 | M6: 3971 | N6: 9275 | O6: 30280 | P6: 1225 | Q6: 1126 | R6: 546 | S6: 3139.7 | T6: 1463.4 | U6: 32509 | V6: 1868.8
A7: 14336 | M7: 3985 | N7: 9309 | O7: 30094 | P7: 1249 | Q7: 1127 | R7: 546 | S7: 3154.8 | T7: 1473.5 | U7: 32874 | V7: 1856
A8: 14366 | M8: 4032 | N8: 9299 | O8: 30299 | P8: 1262 | Q8: 1125 | R8: 550 | S8: 3151.7 | T8: 1480.6 | U8: 33239 | V8: 1896.9
A9: 14397 | M9: 4035 | N9: 9315 | O9: 30502 | P9: 1264 | Q9: 1131 | R9: 553 | S9: 3152.9 | T9: 1484.5 | U9: 33604 | V9: 1903.5
A10: 14427 | M10: 3991 | N10: 9231 | O10: 30419 | P10: 1221 | Q10: 1131 | R10: 555 | S10: 3165.8 | T10: 1491.2 | U10: 33970 | V10: 1966.7
A11: 14458 | M11: 4022 | N11: 9400 | O11: 30663 | P11: 1236 | Q11: 1134 | R11: 555 | S11: 3165.9 | T11: 1493 | U11: 34335 | V11: 2102.1
A12: 14489 | M12: 4140 | N12: 9604 | O12: 31031 | P12: 1203 | Q12: 1152 | R12: 560 | S12: 3185 | T12: 1518.9 | U12: 34700 | V12: 2225.2
A13: 14519 | M13: 4145 | N13: 9873 | O13: 31411 | P13: 1186 | Q13: 1179 | R13: 557 | S13: 3186.1 | T13: 1540.5 | U13: 35065 | V13: 2298.2
A14: 14550 | M14: 4097 | N14: 9896 | O14: 31470 | P14: 1172 | Q14: 1179 | R14: 559 | S14: 3192 | T14: 1531.7 | U14: 35431 | V14: 2371.7
A15: 14580 | M15: 4151 | N15: 9949 | O15: 31542 | P15: 1142 | Q15: 1178 | R15: 562 | S15: 3178.1 | T15: 1534.9 | U15: 35796 | V15: 2439.5
... A41: 15373 | M41: 5094 | N41: 13127 | O41: 38512 | P41: 1900 | Q41: 1415 | R41: 632 | S41: 3579.5 | T41: 1675.3 | U41: 45292 | V41: 4227.2
A42: 15401 | M42: 5248 | N42: 13311 | O42: 38935 | P42: 2042 | Q42: 1426 | R42: 635 | S42: 3566.7 | T42: 1666.2
A43: 15432 | M43: 5374 | N43: 13509 | O43: 39352 | P43: 2170 | Q43: 1440 | R43: 637 | S43: 3542 | T43: 1650.7
A44: 15462 | M44: 5483 | N44: 13704 | O44: 39771 | P44: 2271 | Q44: 1450 | R44: 639 | S44: 3535.8 | T44: 1637.9
A45: 15493 | M45: 5548 | N45: 13842 | O45: 40029 | P45: 2380 | Q45: 1457 | R45: 641 | S45: 3503.1 | T45: 1616.3
A46: 15523 | M46: 5560 | N46: 14072 | O46: 40472 | P46: 2494 | Q46: 1471 | R46: 644 | S46: 3490.9 | T46: 1608.4
A47: 15554 | M47: 5766 | N47: 14339 | O47: 40988 | P47: 2478 | Q47: 1486 | R47: 646 | S47: 3494.6 | T47: 1602.6
A48: 15585 | M48: 5892 | N48: 14582 | O48: 41259 | P48: 2433 | Q48: 1500 | R48: 647 | S48: 3493.5 | T48: 1597
A49: 15615 | M49: 5980 | N49: 14772 | O49: 41515 | P49: 2352 | Q49: 1514 | R49: 647 | S49: 3508.8 | T49: 1593.6
A50: 15646 | M50: 5996 | N50: 14971 | O50: 41674 | P50: 2260 | Q50: 1527 | R50: 646 | S50: 3498.8 | T50: 1580.4
A51: 15676 | M51: 6113 | N51: 15288 | O51: 41915 | P51: 2136 | Q51: 1547 | R51: 646 | S51: 3479.8 | T51: 1567.7
A52: 15707 | M52: 6084 | N52: 15532 | O52: 42172 | P52: 2064 | Q52: 1562 | R52: 648 | S52: 3473.4 | T52: 1563.6
A53: 15738 | M53: 6183 | N53: 15685 | O53: 42393 | P53: 2022 | Q53: 1570 | R53: 649 | S53: 3466.2 | T53: 1561.4
... A231: 21155 | M231: 8159 | N231: 15332 | O231: 52384 | P231: 2935 | Q231: 1740 | R231: 1056 | S231: 5299.9 | T231: 2545.3
A232: 21186 | B232: 760.1 | M232: 7821 | N232: 15130 | O232: 52076 | P232: 2925 | Q232: 1722 | R232: 1052 | S232: 5304.2 | T232: 2540.3
A233: 21217 | B233: 743.4 | M233: 7856 | N233: 14908 | O233: 51576 | P233: 2792 | Q233: 1704 | R233: 1050 | S233: 5270.4 | T233: 2529.2
A234: 21245 | B234: 727.2 | M234: 7884 | N234: 14670 | O234: 51299 | P234: 2853 | Q234: 1684 | R234: 1050 | S234: 5261.4 | T234: 2525.3
A235: 21276 | B235: 707.4 | M235: 7909 | N235: 14506 | O235: 51027 | P235: 2823 | Q235: 1666 | R235: 1050 | S235: 5203.6 | T235: 2524.6
A236: 21306 | B236: 694.6 | M236: 7924 | N236: 14414 | O236: 50914 | P236: 2815 | Q236: 1658 | R236: 1051 | S236: 5234.5 | T236: 2523.4
A237: 21337 | B237: 695.7 | M237: 7920 | N237: 14408 | O237: 50914 | P237: 2796 | Q237: 1655 | R237: 1052 | S237: 5236 | T237: 2530.7
A238: 21367 | B238: 695.2 | M238: 7722 | N238: 14450 | O238: 51039 | P238: 2807 | Q238: 1655 | R238: 1055 | S238: 5243.2 | T238: 2527.8
A239: 21398 | B239: 702.8 | M239: 7734 | N239: 14524 | O239: 51233 | P239: 2833 | Q239: 1656 | R239: 1060 | S239: 5255.8 | T239: 2523.9
A240: 21429 | B240: 709.5 | M240: 7989 | N240: 14658 | O240: 51506 | P240: 2874 | Q240: 1663 | R240: 1063 | S240: 5280.2 | T240: 2527.8
A241: 21459 | B241: 707.3 | M241: 8074 | N241: 14503 | O241: 51485 | P241: 2917 | Q241: 1665 | R241: 1067 | S241: 5291.2 | T241: 2533.4
A242: 21490 | B242: 710.4 | M242: 8103 | N242: 14827 | O242: 51944 | P242: 2982 | Q242: 1678 | R242: 1068 | S242: 5306 | T242: 2542.6
...

Sheet Unemployment Rate by MSA
A1: observation_date | B1: Atlanta-Sandy Springs-Roswell, GA Metro Area | C1: Chicago-Naperville-Elgin, IL-IN Metro Area | D1: Dallas-Fort Worth-Arlington, TX Metro Area | E1: Denver-Aurora-Centennial, CO Metro Area | F1: Houston-Pasadena-The Woodlands, TX Metro Area | G1: Seattle-Tacoma-Bellevue, WA Metro Area | H1: Boston-Cambridge-Newton, MA-NH Metro Area | I1: Los Angeles-Long Beach-Anaheim, CA Metro Area | J1: New York-Newark-Jersey City, NY-NJ Metro Area | K1: Orlando-Kissimmee-Sanford, FL Metro Area | L1: Phoenix-Mesa-Chandler, AZ Metro Area | M1: Riverside-San Bernardino-Ontario, CA Metro Area | N1: San Diego-Chula Vista-Carlsbad, CA Metro Area | O1: San Francisco-Oakland-Fremont, CA Metro Area | P1: USA
A2: Date | B2: Unemployment Rate | C2: Unemployment Rate | D2: Unemployment Rate | E2: Unemployment Rate | F2: Unemployment Rate | G2: Unemployment Rate | H2: Unemployment Rate | I2: Unemployment Rate | J2: Unemployment Rate | K2: Unemployment Rate | L2: Unemployment Rate | M2: Unemployment Rate | N2: Unemployment Rate | O2: Unemployment Rate | P2: Unemployment Rate
A3: Date | B3: =B1&B2 -> Atlanta-Sandy Springs-Roswell, GA Metro AreaUnemployment Rate | C3: =C1&C2 -> Chicago-Naperville-Elgin, IL-IN Metro AreaUnemployment Rate | D3: =D1&D2 -> Dallas-Fort Worth-Arlington, TX Metro AreaUnemployment Rate | E3: =E1&E2 -> Denver-Aurora-Centennial, CO Metro AreaUnemployment Rate | F3: =F1&F2 -> Houston-Pasadena-The Woodlands, TX Metro AreaUnemployment Rate | G3: =G1&G2 -> Seattle-Tacoma-Bellevue, WA Metro AreaUnemployment Rate | H3: =H1&H2 -> Boston-Cambridge-Newton, MA-NH Metro AreaUnemployment Rate | I3: =I1&I2 -> Los Angeles-Long Beach-Anaheim, CA Metro AreaUnemployment Rate | ... P3: =P1&P2 -> USAUnemployment Rate
A4: 17533 | P4: 3.4
A5: 17564 | P5: 3.8
A6: 17593 | P6: 4
A7: 17624 | P7: 3.9
A8: 17654 | P8: 3.5
A9: 17685 | P9: 3.6
A10: 17715 | P10: 3.6
A11: 17746 | P11: 3.9
A12: 17777 | P12: 3.8
A13: 17807 | P13: 3.7
A14: 17838 | P14: 3.8
A15: 17868 | P15: 4
... A507: 32843 | P507: 5.4
A508: 32874 | B508: 4.9 | C508: 6.9 | D508: 4.8 | E508: 5.1 | F508: 5.2 | H508: 5.2 | I508: 5.2 | J508: 5.4 | K508: 5.4 | L508: 4.6 | M508: 5 | N508: 4 | O508: 3.5 | P508: 5.4
A509: 32905 | B509: 5 | C509: 6.6 | D509: 5.2 | E509: 5.1 | F509: 5.1 | H509: 5.3 | I509: 5 | J509: 5.5 | K509: 5.2 | L509: 4.3 | M509: 5.1 | N509: 3.8 | O509: 3.3 | P509: 5.3
A510: 32933 | B510: 4.6 | C510: 6.3 | D510: 4.6 | E510: 5 | F510: 4.7 | H510: 5.3 | I510: 4.8 | J510: 5.2 | K510: 5.1 | L510: 4.3 | M510: 4.8 | N510: 3.7 | O510: 3.1 | P510: 5.2
A511: 32964 | B511: 4.6 | C511: 6.6 | D511: 4.7 | E511: 4.6 | F511: 4.8 | H511: 5.2 | I511: 4.9 | J511: 5 | K511: 5.3 | L511: 4.3 | M511: 5.3 | N511: 3.9 | O511: 3.3 | P511: 5.4
A512: 32994 | B512: 4.6 | C512: 6.2 | D512: 5.1 | E512: 4.3 | F512: 4.9 | H512: 5.3 | I512: 4.9 | J512: 5.1 | K512: 5.3 | L512: 4.3 | M512: 5.4 | N512: 4.1 | O512: 3.3 | P512: 5.4
A513: 33025 | B513: 5.1 | C513: 6.4 | D513: 5.5 | E513: 4.5 | F513: 5.3 | H513: 5.6 | I513: 4.9 | J513: 4.9 | K513: 5.7 | L513: 4.6 | M513: 5.8 | N513: 4.5 | O513: 3.5 | P513: 5.2
A514: 33055 | B514: 4.9 | C514: 6.5 | D514: 5.4 | E514: 4.4 | F514: 5.3 | H514: 5.9 | I514: 5.5 | J514: 5.5 | K514: 5.7 | L514: 4.7 | M514: 7.3 | N514: 5.1 | O514: 4.1 | P514: 5.5
A515: 33086 | B515: 5 | C515: 6.5 | D515: 5.1 | E515: 4.2 | F515: 5.3 | H515: 6.1 | I515: 5.6 | J515: 5.3 | K515: 6 | L515: 4.5 | M515: 7.3 | N515: 5 | O515: 3.9 | P515: 5.7
A516: 33117 | B516: 5.4 | C516: 6.4 | D516: 5.3 | E516: 4.2 | F516: 5.5 | H516: 6.5 | I516: 5.8 | J516: 5.7 | K516: 6.4 | L516: 4.4 | M516: 7.5 | N516: 5.4 | O516: 3.9 | P516: 5.9
A517: 33147 | B517: 5 | C517: 6 | D517: 4.9 | E517: 4.1 | F517: 5 | H517: 6.1 | I517: 5.6 | J517: 5.7 | K517: 6.2 | L517: 4.1 | M517: 7.3 | N517: 5.2 | O517: 3.7 | P517: 5.9
A518: 33178 | B518: 4.9 | C518: 6.1 | D518: 5.4 | E518: 4.3 | F518: 5.2 | H518: 6.5 | I518: 5.8 | J518: 5.8 | K518: 6.5 | L518: 4.1 | M518: 7.6 | N518: 5.4 | O518: 3.9 | P518: 6.2
A519: 33208 | B519: 5 | C519: 6.3 | D519: 5.2 | E519: 4.2 | F519: 5.1 | H519: 6.6 | I519: 5.9 | J519: 5.8 | K519: 6.3 | L519: 4 | M519: 7.4 | N519: 5.3 | O519: 3.8 | P519: 6.3
... A555: 34304 | B555: 4.8 | C555: 6.5 | D555: 5.3 | E555: 4.1 | F555: 6.6 | H555: 5.5 | I555: 8.4 | J555: 7.5 | K555: 5.6 | L555: 4.5 | M555: 9.5 | N555: 6.9 | O555: 5.5 | P555: 6.5
A556: 34335 | B556: 5.5 | C556: 7.8 | D556: 6.1 | E556: 5 | F556: 7.4 | G556: 5.9 | H556: 6.5 | I556: 9.6 | J556: 8.5 | K556: 6.6 | L556: 5.2 | M556: 10.9 | N556: 7.8 | O556: 6.5 | P556: 6.6
A557: 34366 | B557: 5.2 | C557: 7.4 | D557: 6.2 | E557: 4.9 | F557: 7.3 | G557: 5.9 | H557: 6.2 | I557: 9.2 | J557: 8.3 | K557: 6.2 | L557: 4.9 | M557: 10.5 | N557: 7.6 | O557: 6.3 | P557: 6.6
A558: 34394 | B558: 5.1 | C558: 7 | D558: 5.9 | E558: 4.8 | F558: 7.1 | G558: 5.9 | H558: 6 | I558: 9 | J558: 8.1 | K558: 6 | L558: 4.9 | M558: 10 | N558: 7.4 | O558: 6.1 | P558: 6.5
A559: 34425 | B559: 4.6 | C559: 6.4 | D559: 5.5 | E559: 4.1 | F559: 6.8 | G559: 5.8 | H559: 5.5 | I559: 8.8 | J559: 7.5 | K559: 5.8 | L559: 4.5 | M559: 9.7 | N559: 7.2 | O559: 6 | P559: 6.4
A560: 34455 | B560: 4.5 | C560: 5.9 | D560: 5.3 | E560: 3.8 | F560: 6.6 | G560: 5.6 | H560: 5.4 | I560: 8.3 | J560: 7.1 | K560: 5.5 | L560: 4.3 | M560: 9.1 | N560: 6.9 | O560: 5.7 | P560: 6.1
A561: 34486 | B561: 5 | C561: 6.2 | D561: 5.8 | E561: 4 | F561: 7.3 | G561: 5.5 | H561: 5.8 | I561: 8.7 | J561: 7.3 | K561: 5.8 | L561: 4.8 | M561: 9.7 | N561: 7.4 | O561: 6.1 | P561: 6.1
A562: 34516 | B562: 4.4 | C562: 5.9 | D562: 5.7 | E562: 3.8 | F562: 7.1 | G562: 5.4 | H562: 5.9 | I562: 9.1 | J562: 7.5 | K562: 5.8 | L562: 4.8 | M562: 10.7 | N562: 7.8 | O562: 6.5 | P562: 6.1
A563: 34547 | B563: 4.5 | C563: 5.7 | D563: 5.4 | E563: 3.6 | F563: 6.8 | G563: 5.3 | H563: 5.7 | I563: 8.7 | J563: 7.1 | K563: 5.6 | L563: 4.9 | M563: 10.3 | N563: 7.5 | O563: 6.3 | P563: 6
A564: 34578 | B564: 4.4 | C564: 5.3 | D564: 5.1 | E564: 3.3 | F564: 6.6 | G564: 5.3 | H564: 5.6 | I564: 8.1 | J564: 6.8 | K564: 5.4 | L564: 4.9 | M564: 9.8 | N564: 7.2 | O564: 5.9 | P564: 5.9
A565: 34608 | B565: 4.2 | C565: 5.4 | D565: 4.8 | E565: 3.1 | F565: 6.2 | G565: 5.2 | H565: 5.2 | I565: 7.7 | J565: 6.6 | K565: 5.2 | L565: 4.5 | M565: 9.2 | N565: 6.8 | O565: 5.5 | P565: 5.8
A566: 34639 | B566: 4 | C566: 5 | D566: 4.8 | E566: 3.2 | F566: 6 | G566: 5.2 | H566: 5 | I566: 7.3 | J566: 6.3 | K566: 5.1 | L566: 4.1 | M566: 8.4 | N566: 6.2 | O566: 5.1 | P566: 5.6
...

Sheet MSA Employment Base 
B1: Atlanta-Sandy Springs-Roswell, GA Metro Area | C1: Atlanta-Sandy Springs-Roswell, GA Metro Area | D1: Atlanta-Sandy Springs-Roswell, GA Metro Area | E1: Atlanta-Sandy Springs-Roswell, GA Metro Area | F1: Atlanta-Sandy Springs-Roswell, GA Metro Area | G1: Atlanta-Sandy Springs-Roswell, GA Metro Area | H1: Atlanta-Sandy Springs-Roswell, GA Metro Area | I1: Atlanta-Sandy Springs-Roswell, GA Metro Area | J1: Atlanta-Sandy Springs-Roswell, GA Metro Area | K1: Atlanta-Sandy Springs-Roswell, GA Metro Area | L1: Atlanta-Sandy Springs-Roswell, GA Metro Area | M1: Atlanta-Sandy Springs-Roswell, GA Metro Area | N1: Atlanta-Sandy Springs-Roswell, GA Metro Area | O1: Atlanta-Sandy Springs-Roswell, GA Metro Area | P1: Atlanta-Sandy Springs-Roswell, GA Metro Area | Q1: Atlanta-Sandy Springs-Roswell, GA Metro Area | R1: Atlanta-Sandy Springs-Roswell, GA Metro Area | S1: Atlanta-Sandy Springs-Roswell, GA Metro Area | T1: Atlanta-Sandy Springs-Roswell, GA Metro Area | U1: Boston-Cambridge-Newton, MA-NH Metro Area | V1: Boston-Cambridge-Newton, MA-NH Metro Area | W1: Boston-Cambridge-Newton, MA-NH Metro Area | X1: Boston-Cambridge-Newton, MA-NH Metro Area | Y1: Boston-Cambridge-Newton, MA-NH Metro Area | Z1: Boston-Cambridge-Newton, MA-NH Metro Area | AA1: Boston-Cambridge-Newton, MA-NH Metro Area | AB1: Boston-Cambridge-Newton, MA-NH Metro Area | AC1: Boston-Cambridge-Newton, MA-NH Metro Area | AD1: Boston-Cambridge-Newton, MA-NH Metro Area | AE1: Boston-Cambridge-Newton, MA-NH Metro Area | AF1: Boston-Cambridge-Newton, MA-NH Metro Area | AG1: Boston-Cambridge-Newton, MA-NH Metro Area | AH1: Boston-Cambridge-Newton, MA-NH Metro Area | AI1: Boston-Cambridge-Newton, MA-NH Metro Area | AJ1: Boston-Cambridge-Newton, MA-NH Metro Area | AK1: Boston-Cambridge-Newton, MA-NH Metro Area | AL1: Boston-Cambridge-Newton, MA-NH Metro Area | AM1: Boston-Cambridge-Newton, MA-NH Metro Area | AN1: Chicago-Naperville-Elgin, IL-IN Metro Area | AO1: Chicago-Naperville-Elgin, IL-IN Metro Area | AP1: Chicago-Naperville-Elgin, IL-IN Metro Area | AQ1: Chicago-Naperville-Elgin, IL-IN Metro Area | AR1: Chicago-Naperville-Elgin, IL-IN Metro Area | AS1: Chicago-Naperville-Elgin, IL-IN Metro Area | AT1: Chicago-Naperville-Elgin, IL-IN Metro Area | AU1: Chicago-Naperville-Elgin, IL-IN Metro Area | AV1: Chicago-Naperville-Elgin, IL-IN Metro Area | AW1: Chicago-Naperville-Elgin, IL-IN Metro Area | AX1: Chicago-Naperville-Elgin, IL-IN Metro Area | AY1: Chicago-Naperville-Elgin, IL-IN Metro Area | AZ1: Chicago-Naperville-Elgin, IL-IN Metro Area | BA1: Chicago-Naperville-Elgin, IL-IN Metro Area | BB1: Chicago-Naperville-Elgin, IL-IN Metro Area | BC1: Chicago-Naperville-Elgin, IL-IN Metro Area | BD1: Chicago-Naperville-Elgin, IL-IN Metro Area | BE1: Dallas-Fort Worth-Arlington, TX Metro Area | BF1: Dallas-Fort Worth-Arlington, TX Metro Area | BG1: Dallas-Fort Worth-Arlington, TX Metro Area | BH1: Dallas-Fort Worth-Arlington, TX Metro Area | BI1: Dallas-Fort Worth-Arlington, TX Metro Area | BJ1: Dallas-Fort Worth-Arlington, TX Metro Area | BK1: Dallas-Fort Worth-Arlington, TX Metro Area | BL1: Dallas-Fort Worth-Arlington, TX Metro Area | BM1: Dallas-Fort Worth-Arlington, TX Metro Area | BN1: Dallas-Fort Worth-Arlington, TX Metro Area | BO1: Dallas-Fort Worth-Arlington, TX Metro Area | BP1: Dallas-Fort Worth-Arlington, TX Metro Area | BQ1: Dallas-Fort Worth-Arlington, TX Metro Area | BR1: Dallas-Fort Worth-Arlington, TX Metro Area | BS1: Dallas-Fort Worth-Arlington, TX Metro Area | BT1: Dallas-Fort Worth-Arlington, TX Metro Area | BU1: Dallas-Fort Worth-Arlington, TX Metro Area | BV1: Dallas-Fort Worth-Arlington, TX Metro Area | BW1: Dallas-Fort Worth-Arlington, TX Metro Area | BX1: Denver-Aurora-Centennial, CO Metro Area | BY1: Denver-Aurora-Centennial, CO Metro Area | BZ1: Denver-Aurora-Centennial, CO Metro Area | CA1: Denver-Aurora-Centennial, CO Metro Area | CB1: Denver-Aurora-Centennial, CO Metro Area | CC1: Denver-Aurora-Centennial, CO Metro Area | CD1: Denver-Aurora-Centennial, CO Metro Area | CE1: Denver-Aurora-Centennial, CO Metro Area | CF1: Denver-Aurora-Centennial, CO Metro Area | CG1: Denver-Aurora-Centennial, CO Metro Area | CH1: Denver-Aurora-Centennial, CO Metro Area | CI1: Denver-Aurora-Centennial, CO Metro Area | CJ1: Denver-Aurora-Centennial, CO Metro Area | CK1: Denver-Aurora-Centennial, CO Metro Area | CL1: Denver-Aurora-Centennial, CO Metro Area | CM1: Denver-Aurora-Centennial, CO Metro Area | CN1: Denver-Aurora-Centennial, CO Metro Area | CO1: Denver-Aurora-Centennial, CO Metro Area | CP1: Denver-Aurora-Centennial, CO Metro Area | CQ1: Detroit-Warren-Dearborn, MI Metro Area | CR1: Detroit-Warren-Dearborn, MI Metro Area | CS1: Detroit-Warren-Dearborn, MI Metro Area | CT1: Detroit-Warren-Dearborn, MI Metro Area | CU1: Detroit-Warren-Dearborn, MI Metro Area | CV1: Detroit-Warren-Dearborn, MI Metro Area | CW1: Detroit-Warren-Dearborn, MI Metro Area | CX1: Detroit-Warren-Dearborn, MI Metro Area | CY1: Detroit-Warren-Dearborn, MI Metro Area | CZ1: Detroit-Warren-Dearborn, MI Metro Area | DA1: Detroit-Warren-Dearborn, MI Metro Area | DB1: Detroit-Warren-Dearborn, MI Metro Area | DC1: Detroit-Warren-Dearborn, MI Metro Area | DD1: Detroit-Warren-Dearborn, MI Metro Area | DE1: Detroit-Warren-Dearborn, MI Metro Area | DF1: Detroit-Warren-Dearborn, MI Metro Area | DG1: Houston-Pasadena-The Woodlands, TX Metro Area | DH1: Houston-Pasadena-The Woodlands, TX Metro Area | DI1: Houston-Pasadena-The Woodlands, TX Metro Area | DJ1: Houston-Pasadena-The Woodlands, TX Metro Area | DK1: Houston-Pasadena-The Woodlands, TX Metro Area | DL1: Houston-Pasadena-The Woodlands, TX Metro Area | DM1: Houston-Pasadena-The Woodlands, TX Metro Area | DN1: Houston-Pasadena-The Woodlands, TX Metro Area | DO1: Houston-Pasadena-The Woodlands, TX Metro Area | DP1: Houston-Pasadena-The Woodlands, TX Metro Area | DQ1: Houston-Pasadena-The Woodlands, TX Metro Area | DR1: Houston-Pasadena-The Woodlands, TX Metro Area | DS1: Houston-Pasadena-The Woodlands, TX Metro Area | DT1: Houston-Pasadena-The Woodlands, TX Metro Area | DU1: Houston-Pasadena-The Woodlands, TX Metro Area | DV1: Houston-Pasadena-The Woodlands, TX Metro Area | DW1: Houston-Pasadena-The Woodlands, TX Metro Area | DX1: Houston-Pasadena-The Woodlands, TX Metro Area | DY1: Houston-Pasadena-The Woodlands, TX Metro Area | DZ1: Los Angeles-Long Beach-Anaheim, CA Metro Area | EA1: Los Angeles-Long Beach-Anaheim, CA Metro Area | EB1: Los Angeles-Long Beach-Anaheim, CA Metro Area | EC1: Los Angeles-Long Beach-Anaheim, CA Metro Area | ED1: Los Angeles-Long Beach-Anaheim, CA Metro Area | EE1: Los Angeles-Long Beach-Anaheim, CA Metro Area | EF1: Los Angeles-Long Beach-Anaheim, CA Metro Area | EG1: Los Angeles-Long Beach-Anaheim, CA Metro Area | EH1: Los Angeles-Long Beach-Anaheim, CA Metro Area | EI1: Los Angeles-Long Beach-Anaheim, CA Metro Area | EJ1: Los Angeles-Long Beach-Anaheim, CA Metro Area | EK1: Los Angeles-Long Beach-Anaheim, CA Metro Area | EL1: Los Angeles-Long Beach-Anaheim, CA Metro Area | EM1: Los Angeles-Long Beach-Anaheim, CA Metro Area | EN1: Los Angeles-Long Beach-Anaheim, CA Metro Area | EO1: Los Angeles-Long Beach-Anaheim, CA Metro Area | EP1: Los Angeles-Long Beach-Anaheim, CA Metro Area | EQ1: Los Angeles-Long Beach-Anaheim, CA Metro Area | ER1: Los Angeles-Long Beach-Anaheim, CA Metro Area | ES1: Miami-Fort Lauderdale-West Palm Beach, FL Metro Area | ET1: Miami-Fort Lauderdale-West Palm Beach, FL Metro Area | EU1: Miami-Fort Lauderdale-West Palm Beach, FL Metro Area | EV1: Miami-Fort Lauderdale-West Palm Beach, FL Metro Area | EW1: Miami-Fort Lauderdale-West Palm Beach, FL Metro Area | EX1: Miami-Fort Lauderdale-West Palm Beach, FL Metro Area | EY1: Miami-Fort Lauderdale-West Palm Beach, FL Metro Area | EZ1: Miami-Fort Lauderdale-West Palm Beach, FL Metro Area | FA1: Miami-Fort Lauderdale-West Palm Beach, FL Metro Area | FB1: Miami-Fort Lauderdale-West Palm Beach, FL Metro Area | FC1: Miami-Fort Lauderdale-West Palm Beach, FL Metro Area | FD1: Miami-Fort Lauderdale-West Palm Beach, FL Metro Area | FE1: Miami-Fort Lauderdale-West Palm Beach, FL Metro Area | FF1: Miami-Fort Lauderdale-West Palm Beach, FL Metro Area | FG1: Miami-Fort Lauderdale-West Palm Beach, FL Metro Area | FH1: Miami-Fort Lauderdale-West Palm Beach, FL Metro Area | FI1: Miami-Fort Lauderdale-West Palm Beach, FL Metro Area | FJ1: Minneapolis-St. Paul-Bloomington, MN-WI Metro Area | FK1: Minneapolis-St. Paul-Bloomington, MN-WI Metro Area | FL1: Minneapolis-St. Paul-Bloomington, MN-WI Metro Area | FM1: Minneapolis-St. Paul-Bloomington, MN-WI Metro Area | FN1: Minneapolis-St. Paul-Bloomington, MN-WI Metro Area | FO1: Minneapolis-St. Paul-Bloomington, MN-WI Metro Area | FP1: Minneapolis-St. Paul-Bloomington, MN-WI Metro Area | FQ1: Minneapolis-St. Paul-Bloomington, MN-WI Metro Area | FR1: Minneapolis-St. Paul-Bloomington, MN-WI Metro Area | FS1: Minneapolis-St. Paul-Bloomington, MN-WI Metro Area | FT1: Minneapolis-St. Paul-Bloomington, MN-WI Metro Area | FU1: Minneapolis-St. Paul-Bloomington, MN-WI Metro Area | FV1: Minneapolis-St. Paul-Bloomington, MN-WI Metro Area | FW1: Minneapolis-St. Paul-Bloomington, MN-WI Metro Area | FX1: Minneapolis-St. Paul-Bloomington, MN-WI Metro Area | FY1: Minneapolis-St. Paul-Bloomington, MN-WI Metro Area | FZ1: Minneapolis-St. Paul-Bloomington, MN-WI Metro Area | GA1: Minneapolis-St. Paul-Bloomington, MN-WI Metro Area | GB1: New York-Newark-Jersey City, NY-NJ Metro Area | GC1: New York-Newark-Jersey City, NY-NJ Metro Area | GD1: New York-Newark-Jersey City, NY-NJ Metro Area | GE1: New York-Newark-Jersey City, NY-NJ Metro Area | GF1: New York-Newark-Jersey City, NY-NJ Metro Area | GG1: New York-Newark-Jersey City, NY-NJ Metro Area | GH1: New York-Newark-Jersey City, NY-NJ Metro Area | GI1: New York-Newark-Jersey City, NY-NJ Metro Area | GJ1: New York-Newark-Jersey City, NY-NJ Metro Area | GK1: New York-Newark-Jersey City, NY-NJ Metro Area | GL1: New York-Newark-Jersey City, NY-NJ Metro Area | GM1: New York-Newark-Jersey City, NY-NJ Metro Area | GN1: New York-Newark-Jersey City, NY-NJ Metro Area | GO1: New York-Newark-Jersey City, NY-NJ Metro Area | GP1: New York-Newark-Jersey City, NY-NJ Metro Area | GQ1: New York-Newark-Jersey City, NY-NJ Metro Area | GR1: New York-Newark-Jersey City, NY-NJ Metro Area | GS1: New York-Newark-Jersey City, NY-NJ Metro Area | GT1: New York-Newark-Jersey City, NY-NJ Metro Area | GU1: Orlando-Kissimmee-Sanford, FL Metro Area | GV1: Orlando-Kissimmee-Sanford, FL Metro Area | GW1: Orlando-Kissimmee-Sanford, FL Metro Area | GX1: Orlando-Kissimmee-Sanford, FL Metro Area | GY1: Orlando-Kissimmee-Sanford, FL Metro Area | GZ1: Orlando-Kissimmee-Sanford, FL Metro Area | HA1: Orlando-Kissimmee-Sanford, FL Metro Area | HB1: Orlando-Kissimmee-Sanford, FL Metro Area | HC1: Orlando-Kissimmee-Sanford, FL Metro Area | HD1: Orlando-Kissimmee-Sanford, FL Metro Area | HE1: Orlando-Kissimmee-Sanford, FL Metro Area | HF1: Orlando-Kissimmee-Sanford, FL Metro Area | HG1: Orlando-Kissimmee-Sanford, FL Metro Area | HH1: Orlando-Kissimmee-Sanford, FL Metro Area | HI1: Orlando-Kissimmee-Sanford, FL Metro Area | HJ1: Orlando-Kissimmee-Sanford, FL Metro Area | HK1: Orlando-Kissimmee-Sanford, FL Metro Area | HL1: Orlando-Kissimmee-Sanford, FL Metro Area | HM1: Orlando-Kissimmee-Sanford, FL Metro Area | HN1: Philadelphia-Camden-Wilmington, PA-NJ-DE-MD Metro Area | HO1: Philadelphia-Camden-Wilmington, PA-NJ-DE-MD Metro Area | HP1: Philadelphia-Camden-Wilmington, PA-NJ-DE-MD Metro Area | HQ1: Philadelphia-Camden-Wilmington, PA-NJ-DE-MD Metro Area | HR1: Philadelphia-Camden-Wilmington, PA-NJ-DE-MD Metro Area | HS1: Philadelphia-Camden-Wilmington, PA-NJ-DE-MD Metro Area | HT1: Philadelphia-Camden-Wilmington, PA-NJ-DE-MD Metro Area | HU1: Philadelphia-Camden-Wilmington, PA-NJ-DE-MD Metro Area | HV1: Philadelphia-Camden-Wilmington, PA-NJ-DE-MD Metro Area | HW1: Philadelphia-Camden-Wilmington, PA-NJ-DE-MD Metro Area | HX1: Philadelphia-Camden-Wilmington, PA-NJ-DE-MD Metro Area | HY1: Philadelphia-Camden-Wilmington, PA-NJ-DE-MD Metro Area | HZ1: Philadelphia-Camden-Wilmington, PA-NJ-DE-MD Metro Area | IA1: Philadelphia-Camden-Wilmington, PA-NJ-DE-MD Metro Area | IB1: Philadelphia-Camden-Wilmington, PA-NJ-DE-MD Metro Area | IC1: Philadelphia-Camden-Wilmington, PA-NJ-DE-MD Metro Area | ID1: Philadelphia-Camden-Wilmington, PA-NJ-DE-MD Metro Area | IE1: Philadelphia-Camden-Wilmington, PA-NJ-DE-MD Metro Area | IF1: Phoenix-Mesa-Chandler, AZ Metro Area | IG1: Phoenix-Mesa-Chandler, AZ Metro Area | IH1: Phoenix-Mesa-Chandler, AZ Metro Area | II1: Phoenix-Mesa-Chandler, AZ Metro Area | IJ1: Phoenix-Mesa-Chandler, AZ Metro Area | IK1: Phoenix-Mesa-Chandler, AZ Metro Area | IL1: Phoenix-Mesa-Chandler, AZ Metro Area | IM1: Phoenix-Mesa-Chandler, AZ Metro Area | IN1: Phoenix-Mesa-Chandler, AZ Metro Area | IO1: Phoenix-Mesa-Chandler, AZ Metro Area | IP1: Phoenix-Mesa-Chandler, AZ Metro Area | IQ1: Phoenix-Mesa-Chandler, AZ Metro Area | IR1: Phoenix-Mesa-Chandler, AZ Metro Area | IS1: Phoenix-Mesa-Chandler, AZ Metro Area | IT1: Phoenix-Mesa-Chandler, AZ Metro Area | IU1: Phoenix-Mesa-Chandler, AZ Metro Area | IV1: Phoenix-Mesa-Chandler, AZ Metro Area | IW1: Phoenix-Mesa-Chandler, AZ Metro Area | IX1: Phoenix-Mesa-Chandler, AZ Metro Area | IY1: Riverside-San Bernardino-Ontario, CA Metro Area | IZ1: Riverside-San Bernardino-Ontario, CA Metro Area | JA1: Riverside-San Bernardino-Ontario, CA Metro Area | JB1: Riverside-San Bernardino-Ontario, CA Metro Area | JC1: Riverside-San Bernardino-Ontario, CA Metro Area | JD1: Riverside-San Bernardino-Ontario, CA Metro Area | JE1: Riverside-San Bernardino-Ontario, CA Metro Area | JF1: Riverside-San Bernardino-Ontario, CA Metro Area | JG1: Riverside-San Bernardino-Ontario, CA Metro Area | JH1: Riverside-San Bernardino-Ontario, CA Metro Area | JI1: Riverside-San Bernardino-Ontario, CA Metro Area | JJ1: Riverside-San Bernardino-Ontario, CA Metro Area | JK1: Riverside-San Bernardino-Ontario, CA Metro Area | JL1: Riverside-San Bernardino-Ontario, CA Metro Area | JM1: Riverside-San Bernardino-Ontario, CA Metro Area | JN1: Riverside-San Bernardino-Ontario, CA Metro Area | JO1: Riverside-San Bernardino-Ontario, CA Metro Area | JP1: Riverside-San Bernardino-Ontario, CA Metro Area | JQ1: Riverside-San Bernardino-Ontario, CA Metro Area | JR1: San Diego-Chula Vista-Carlsbad, CA Metro Area | JS1: San Diego-Chula Vista-Carlsbad, CA Metro Area | JT1: San Diego-Chula Vista-Carlsbad, CA Metro Area | JU1: San Diego-Chula Vista-Carlsbad, CA Metro Area | JV1: San Diego-Chula Vista-Carlsbad, CA Metro Area | JW1: San Diego-Chula Vista-Carlsbad, CA Metro Area | JX1: San Diego-Chula Vista-Carlsbad, CA Metro Area | JY1: San Diego-Chula Vista-Carlsbad, CA Metro Area | JZ1: San Diego-Chula Vista-Carlsbad, CA Metro Area | KA1: San Diego-Chula Vista-Carlsbad, CA Metro Area | KB1: San Diego-Chula Vista-Carlsbad, CA Metro Area | KC1: San Diego-Chula Vista-Carlsbad, CA Metro Area | KD1: San Diego-Chula Vista-Carlsbad, CA Metro Area | KE1: San Diego-Chula Vista-Carlsbad, CA Metro Area | KF1: San Diego-Chula Vista-Carlsbad, CA Metro Area | KG1: San Diego-Chula Vista-Carlsbad, CA Metro Area | KH1: San Diego-Chula Vista-Carlsbad, CA Metro Area | KI1: San Diego-Chula Vista-Carlsbad, CA Metro Area | KJ1: San Diego-Chula Vista-Carlsbad, CA Metro Area | KK1: San Francisco-Oakland-Fremont, CA Metro Area | KL1: San Francisco-Oakland-Fremont, CA Metro Area | KM1: San Francisco-Oakland-Fremont, CA Metro Area | KN1: San Francisco-Oakland-Fremont, CA Metro Area | KO1: San Francisco-Oakland-Fremont, CA Metro Area | KP1: San Francisco-Oakland-Fremont, CA Metro Area | KQ1: San Francisco-Oakland-Fremont, CA Metro Area | KR1: San Francisco-Oakland-Fremont, CA Metro Area | KS1: San Francisco-Oakland-Fremont, CA Metro Area | KT1: San Francisco-Oakland-Fremont, CA Metro Area | KU1: San Francisco-Oakland-Fremont, CA Metro Area | KV1: San Francisco-Oakland-Fremont, CA Metro Area | KW1: San Francisco-Oakland-Fremont, CA Metro Area | KX1: San Francisco-Oakland-Fremont, CA Metro Area | KY1: San Francisco-Oakland-Fremont, CA Metro Area | KZ1: San Francisco-Oakland-Fremont, CA Metro Area | LA1: San Francisco-Oakland-Fremont, CA Metro Area | LB1: San Francisco-Oakland-Fremont, CA Metro Area | LC1: San Francisco-Oakland-Fremont, CA Metro Area | LD1: Seattle-Tacoma-Bellevue, WA Metro Area | LE1: Seattle-Tacoma-Bellevue, WA Metro Area | LF1: Seattle-Tacoma-Bellevue, WA Metro Area | LG1: Seattle-Tacoma-Bellevue, WA Metro Area | LH1: Seattle-Tacoma-Bellevue, WA Metro Area | LI1: Seattle-Tacoma-Bellevue, WA Metro Area | LJ1: Seattle-Tacoma-Bellevue, WA Metro Area | LK1: Seattle-Tacoma-Bellevue, WA Metro Area | LL1: Seattle-Tacoma-Bellevue, WA Metro Area | LM1: Seattle-Tacoma-Bellevue, WA Metro Area | LN1: Seattle-Tacoma-Bellevue, WA Metro Area | LO1: Seattle-Tacoma-Bellevue, WA Metro Area | LP1: Seattle-Tacoma-Bellevue, WA Metro Area | LQ1: Seattle-Tacoma-Bellevue, WA Metro Area | LR1: Seattle-Tacoma-Bellevue, WA Metro Area | LS1: Seattle-Tacoma-Bellevue, WA Metro Area | LT1: Seattle-Tacoma-Bellevue, WA Metro Area | LU1: Seattle-Tacoma-Bellevue, WA Metro Area | LV1: Seattle-Tacoma-Bellevue, WA Metro Area | LW1: Tampa-St. Petersburg-Clearwater, FL Metro Area | LX1: Tampa-St. Petersburg-Clearwater, FL Metro Area | LY1: Tampa-St. Petersburg-Clearwater, FL Metro Area | LZ1: Tampa-St. Petersburg-Clearwater, FL Metro Area | MA1: Tampa-St. Petersburg-Clearwater, FL Metro Area | MB1: Tampa-St. Petersburg-Clearwater, FL Metro Area | MC1: Tampa-St. Petersburg-Clearwater, FL Metro Area | MD1: Tampa-St. Petersburg-Clearwater, FL Metro Area | ME1: Tampa-St. Petersburg-Clearwater, FL Metro Area | MF1: Tampa-St. Petersburg-Clearwater, FL Metro Area | MG1: Tampa-St. Petersburg-Clearwater, FL Metro Area | MH1: Tampa-St. Petersburg-Clearwater, FL Metro Area | MI1: Tampa-St. Petersburg-Clearwater, FL Metro Area | MJ1: Tampa-St. Petersburg-Clearwater, FL Metro Area | MK1: Tampa-St. Petersburg-Clearwater, FL Metro Area | ML1: Tampa-St. Petersburg-Clearwater, FL Metro Area | MM1: Tampa-St. Petersburg-Clearwater, FL Metro Area | MN1: Tampa-St. Petersburg-Clearwater, FL Metro Area | MO1: Washington-Arlington-Alexandria, DC-VA-MD-WV Metro Area | MP1: Washington-Arlington-Alexandria, DC-VA-MD-WV Metro Area | MQ1: Washington-Arlington-Alexandria, DC-VA-MD-WV Metro Area | MR1: Washington-Arlington-Alexandria, DC-VA-MD-WV Metro Area | MS1: Washington-Arlington-Alexandria, DC-VA-MD-WV Metro Area | MT1: Washington-Arlington-Alexandria, DC-VA-MD-WV Metro Area | MU1: Washington-Arlington-Alexandria, DC-VA-MD-WV Metro Area | MV1: Washington-Arlington-Alexandria, DC-VA-MD-WV Metro Area | MW1: Washington-Arlington-Alexandria, DC-VA-MD-WV Metro Area | MX1: Washington-Arlington-Alexandria, DC-VA-MD-WV Metro Area | MY1: Washington-Arlington-Alexandria, DC-VA-MD-WV Metro Area | MZ1: Washington-Arlington-Alexandria, DC-VA-MD-WV Metro Area | NA1: Washington-Arlington-Alexandria, DC-VA-MD-WV Metro Area | NB1: Washington-Arlington-Alexandria, DC-VA-MD-WV Metro Area | NC1: Washington-Arlington-Alexandria, DC-VA-MD-WV Metro Area | ND1: Washington-Arlington-Alexandria, DC-VA-MD-WV Metro Area | NE1: Washington-Arlington-Alexandria, DC-VA-MD-WV Metro Area | NF1: Washington-Arlington-Alexandria, DC-VA-MD-WV Metro Area | NG1: US | NH1: US | NI1: US | NJ1: US | NK1: US | NL1: US | NM1: US | NN1: US | NO1: US | NP1: US | NQ1: US | NR1: US | NS1: US | NT1: US | NU1: US | NV1: US | NW1: US | NX1: US | NY1: US | NZ1: US
